Workbook

Sheet TRANGCHU
A1: BỘ TÀI LIỆU MẪU GIÁO 3-6 TUỔI
A2: THEO CHƯƠNG TRÌNH GIÁO DỤC MẦM NON THÍ ĐIỂM (QĐ 388/QĐ-BGDĐT)
A3: Năm học 2026-2027 · Khối MGB (3-4t) - MGN (4-5t) - MGL (5-6t)
A6: STT | B6: Mã sheet (bấm để đi tới) | C6: Nội dung | D6: Nhóm
A7: NỀN TẢNG
A8: 1 | B8: =HYPERLINK("#TRANGCHU!A1","TRANGCHU") -> TRANGCHU | C8: Trang chủ | D8: NỀN TẢNG
A9: 2 | B9: =HYPERLINK("#HUONGDAN!A1","HUONGDAN") -> HUONGDAN | C9: Hướng dẫn sử dụng (gồm cả Triết lý - Nguyên tắc - Mã hóa) | D9: NỀN TẢNG
A10: KHUNG CHUYÊN MÔN
A11: 3 | B11: =HYPERLINK("#KHUNGNL!A1","KHUNGNL") -> KHUNGNL | C11: Khung năng lực 3-6 tuổi | D11: KHUNG CHUYÊN MÔN
A12: 4 | B12: =HYPERLINK("#MOCPT!A1","MOCPT") -> MOCPT | C12: Mốc phát triển 36-72 tháng | D12: KHUNG CHUYÊN MÔN
A13: 5 | B13: =HYPERLINK("#MATRANYCCD!A1","MATRANYCCD") -> MATRANYCCD | C13: Ma trận YCCĐ (388 đối chiếu 4222) | D13: KHUNG CHUYÊN MÔN
A14: KẾ HOẠCH GIÁO DỤC
A15: 6 | B15: =HYPERLINK("#KHNAM_3_4T!A1","KHNAM_3_4T") -> KHNAM_3_4T | C15: Kế hoạch năm 3-4 tuổi | D15: KẾ HOẠCH GIÁO DỤC
A16: 7 | B16: =HYPERLINK("#KHNAM_4_5T!A1","KHNAM_4_5T") -> KHNAM_4_5T | C16: Kế hoạch năm 4-5 tuổi | D16: KẾ HOẠCH GIÁO DỤC
A17: 8 | B17: =HYPERLINK("#KHNAM_5_6T!A1","KHNAM_5_6T") -> KHNAM_5_6T | C17: Kế hoạch năm 5-6 tuổi | D17: KẾ HOẠCH GIÁO DỤC
A18: 9 | B18: =HYPERLINK("#PHIENCHE!A1","PHIENCHE") -> PHIENCHE | C18: Phiên chế 35 tuần chung | D18: KẾ HOẠCH GIÁO DỤC
A19: HOẠT ĐỘNG & HỌC LIỆU
A20: 10 | B20: =HYPERLINK("#NGANHANGHD!A1","NGANHANGHD") -> NGANHANGHD | C20: Ngân hàng hoạt động | D20: HOẠT ĐỘNG & HỌC LIỆU
A21: 11 | B21: =HYPERLINK("#NGANHANGHL!A1","NGANHANGHL") -> NGANHANGHL | C21: Ngân hàng học liệu | D21: HOẠT ĐỘNG & HỌC LIỆU
A22: CÔNG CỤ ĐÁNH GIÁ THỰC ĐỊA
A23: 12 | B23: =HYPERLINK("#RUBRIC!A1","RUBRIC") -> RUBRIC | C23: Rubric đánh giá năng lực | D23: CÔNG CỤ ĐÁNH GIÁ THỰC ĐỊA
A24: 13 | B24: =HYPERLINK("#PHIEUCANHAN!A1","PHIEUCANHAN") -> PHIEUCANHAN | C24: Phiếu cá nhân trẻ | D24: CÔNG CỤ ĐÁNH GIÁ THỰC ĐỊA
A25: 14 | B25: =HYPERLINK("#BANGKIEMLOP!A1","BANGKIEMLOP") -> BANGKIEMLOP | C25: Bảng kiểm lớp | D25: CÔNG CỤ ĐÁNH GIÁ THỰC ĐỊA
A26: 15 | B26: =HYPERLINK("#NHATKYQUANSAT!A1","NHATKYQUANSAT") -> NHATKYQUANSAT | C26: Nhật ký quan sát | D26: CÔNG CỤ ĐÁNH GIÁ THỰC ĐỊA
A27: 16 | B27: =HYPERLINK("#PHIEUTRAODOI!A1","PHIEUTRAODOI") -> PHIEUTRAODOI | C27: Phiếu trao đổi phụ huynh | D27: CÔNG CỤ ĐÁNH GIÁ THỰC ĐỊA
A28: 17 | B28: =HYPERLINK("#PORTFOLIO!A1","PORTFOLIO") -> PORTFOLIO | C28: Portfolio trẻ | D28: CÔNG CỤ ĐÁNH GIÁ THỰC ĐỊA
A29: QUẢN LÝ
A30: 18 | B30: =HYPERLINK("#DASHBOARD_LOP!A1","DASHBOARD_LOP") -> DASHBOARD_LOP | C30: Dashboard lớp | D30: QUẢN LÝ
A31: 19 | B31: =HYPERLINK("#DASHBOARD_TOANTRUONG!A1","DASHBOARD_TOANTRUONG") -> DASHBOARD_TOANTRUONG | C31: Dashboard toàn trường | D31: QUẢN LÝ
A33: © 2026-2027 Insight Institute — Bộ tài liệu Mẫu giáo 3-6 tuổi theo Chương trình GDMN thí điểm QĐ 388. Bản quyền nội dung thuộc về đơn vị biên soạn.

Sheet HUONGDAN
A1: HƯỚNG DẪN SỬ DỤNG BỘ TÀI LIỆU | C1: =HYPERLINK("#TRANGCHU!A1","⬅ Về Trang chủ") -> ⬅ Về Trang chủ
A2: Dành cho Giáo viên và Cán bộ quản lý · File không khóa dữ liệu — có thể điều chỉnh trực tiếp theo điều kiện thực tế của lớp/trường.
A4: 1. NGUYÊN TẮC VÀNG KHI SỬ DỤNG
A5: • YCCĐ cuối 5-6 tuổi là đích chung cả 3 độ tuổi hướng tới, không phải chuẩn phải đạt ngay ở lớp Bé/Nhỡ.
A6: • 3 mức I (Khởi đầu/Hình thành ban đầu) → R (Củng cố) → V/M (Vững chắc/Thành thạo) là bậc thang liên thông 3 năm, KHÔNG phải chuẩn chấm điểm riêng từng lớp.
A7: • Mỗi trẻ có thể ở một mức khác nhau tại cùng thời điểm — đây là điều bình thường, không dùng để so sánh hay xếp loại trẻ.
A8: • Dùng mức I/H/V để CHỌN HOẠT ĐỘNG phù hợp, không dùng để kết luận về trẻ sau một lần quan sát.
A9: • Đánh giá bằng QUAN SÁT và MINH CHỨNG trong sinh hoạt tự nhiên hằng ngày — không kiểm tra kiến thức, không tạo áp lực cho trẻ.
A10: • Riêng khối MGL (5-6 tuổi): đối chiếu thêm QĐ 4222 vì đây là bộ chuẩn quốc gia duy nhất, chỉ áp dụng cho trẻ 5 tuổi.
A12: 2. QUY TRÌNH SỬ DỤNG THEO NĂM HỌC
A13: • Đầu năm: xem KHUNGNL + KHNAM (theo đúng độ tuổi lớp mình) để nắm mục tiêu năm học.
A14: • Hằng tuần: dùng PHIENCHE để biết chủ đề, trục năng lực trọng tâm; tham khảo NGANHANGHD + NGANHANGHL để chọn hoạt động và chuẩn bị học liệu.
A15: • Hằng ngày/tuần: ghi NHATKYQUANSAT khi có minh chứng cụ thể (hành vi/câu nói/sản phẩm) — không viết nhận xét chung chung.
... A42: B. BẢNG MÃ HÓA 5 LĨNH VỰC PHÁT TRIỂN (QĐ 388)
A43: Ký hiệu | B43: Lĩnh vực | C43: Số nhóm năng lực
A44: TC | B44: Thể chất | C44: 7
A45: TX | B45: Tình cảm - xã hội | C45: 8
A46: NN | B46: Ngôn ngữ và giao tiếp | C46: 4
A47: NT | B47: Nhận thức | C47: 6
A48: NgT | B48: Nghệ thuật/Thẩm mĩ | C48: 5
A50: C. THANG MỨC PHÁT TRIỂN LIÊN THÔNG 3 ĐỘ TUỔI
A51: Mức | B51: Tên gọi | C51: Áp dụng cho | D51: Ý nghĩa
A52: I | B52: Hình thành | C52: MGB (3-4 tuổi) | D52: Trẻ mới làm quen, cần hỗ trợ toàn phần/một phần từ GV
A53: R | B53: Củng cố | C53: MGN (4-5 tuổi) | D53: Trẻ thực hiện tốt trong tình huống quen thuộc, cần hỗ trợ nhẹ
A54: M/V | B54: Thành thạo/Vững chắc | C54: MGL (5-6 tuổi) | D54: Trẻ chủ động, ít/không cần hỗ trợ, vận dụng linh hoạt
A56: D. THANG ĐÁNH GIÁ RUBRIC (dùng nội bộ trong 1 độ tuổi)
A57: Ký hiệu | B57: Tên gọi | C57: Mô tả
A58: I | B58: Khởi đầu | C58: Trẻ mới bắt đầu thể hiện dấu hiệu, cần hỗ trợ toàn phần, chưa ổn định
A59: H | B59: Hình thành | C59: Trẻ thể hiện được trong một số tình huống quen thuộc, cần hỗ trợ một phần
A60: V | B60: Vững chắc | C60: Trẻ thể hiện ổn định, chủ động, ít/không cần hỗ trợ, có thể vận dụng
A61: X | B61: Chưa có cơ hội quan sát | C61: Chưa đủ minh chứng — không suy diễn, không mặc định vào mức nào
A63: E. 4 PHẨM CHẤT VÀ 5 NĂNG LỰC NỀN TẢNG
A64: Phẩm chất: Yêu thương - Tôn trọng - Trung thực - Trách nhiệm
A65: Năng lực nền tảng: Giao tiếp - Hợp tác - Giải quyết vấn đề - Thích ứng - Tự lực
A66: Lưu ý: KHÔNG dùng "Sáng tạo" như một năng lực nền tảng độc lập ở nhóm này — sáng tạo được lồng ghép trong nội dung từng lĩnh vực (đặc biệt Nghệ thuật), tránh nhầm lẫn với 5 năng lực nền tảng chính thức nêu trên.
A69: NHẬT KÝ CHỈNH SỬA BỘ TÀI LIỆU
A70: Ghi lại lịch sử hoàn thiện để tổ chuyên môn/nhà trường theo dõi minh bạch — không phản ánh việc "sửa lỗi" mà là quá trình hoàn thiện liên tục theo tinh thần chương trình thí điểm.
A72: Phiên bản | B72: Nội dung chỉnh sửa chính | C72: Lý do / Căn cứ
A73: v1.0 | B73: Xây dựng kiến trúc tổng thể 16-20 sheet cho Bộ tài liệu Mẫu giáo 3-6 tuổi, dựa trên cấu trúc đã kiểm chứng của Bộ Nhà trẻ 12-36 tháng. | C73: Kế thừa mô hình đã vận hành tốt, đảm bảo tính nhất quán liên thông 4 độ tuổi.
A74: v1.1 | B74: Xây Khung năng lực 30 mã × 3 độ tuổi (I-R-M), Mục tiêu năm học 3 độ tuổi, Phiên chế 35 tuần chung, Ngân hàng hoạt động (30 mẫu), Rubric, Bảng kiểm lớp, Nhật ký quan sát, Phiếu trao đổi CMHS, Portfolio, Dashboard. | C74: Bám QĐ 388, đối chiếu QĐ 4222 (riêng MGL), dữ liệu gốc từ Mục tiêu năm học và Phiên chế 3 độ tuổi đã cung cấp.
...

Sheet KHUNGNL
A1: KHUNG NĂNG LỰC MẪU GIÁO 3-6 TUỔI — LIÊN THÔNG I → R → M | K1: =HYPERLINK("#TRANGCHU!A1","⬅ Về Trang chủ") -> ⬅ Về Trang chủ | L1: =HYPERLINK("#HUONGDAN!A1","📖 Về Hướng dẫn") -> 📖 Về Hướng dẫn
A2: Căn cứ QĐ 388 · 30 nhóm năng lực × 5 lĩnh vực · gắn 4 phẩm chất và 5 năng lực nền tảng
A4: Lĩnh vực | B4: Mã | C4: Tên năng lực | D4: 3-4 tuổi (I) | E4: 4-5 tuổi (R) | F4: 5-6 tuổi (M) | G4: Minh chứng quan sát | H4: NL nền tảng | I4: Phẩm chất
A5: Thể chất | B5: TC1 | C5: Chủ động tham gia hoạt động thể chất | D5: Chủ động rủ bạn/tự chọn tham gia hoạt động thể chất mà không cần cô rủ trước; cố gắng hoàn thành dù hơi mệt, chỉ nghỉ khi thực sự cần. | E5: Tự đặt mục tiêu nhỏ cho bản thân khi vận động (VD: bật xa hơn lần trước) và cố gắng đạt được, ít cần cô động viên giữa chừng. | F5: Chủ động, hào hứng, không bỏ cuộc cho đến khi đạt mục tiêu vận động. | G5: Trẻ tự giác xếp hàng tập thể dục, kiên trì hoàn thành bài tập dù khó. | H5: Tự lực, Thích ứng | I5: Trách nhiệm
A6: Thể chất | B6: TC2 | C6: Thích ứng thay đổi vận động/sinh hoạt | D6: Tự điều chỉnh khi có thay đổi nhỏ, quen thuộc trong giờ vận động/sinh hoạt (đổi chỗ chơi, đổi bạn cùng nhóm) mà không cần cô trấn an nhiều. | E6: Thích ứng nhanh với hầu hết thay đổi trong sinh hoạt/vận động, kể cả thay đổi chưa quen nếu được báo trước. | F6: Chủ động đáp ứng khi có thay đổi hoạt động/sinh hoạt; dễ hòa nhập môi trường mới. | G6: Trẻ nhanh chóng bắt nhịp khi đổi giờ hoạt động hoặc chuyển sang sân chơi mới. | H6: Thích ứng | I6: —
A7: Thể chất | B7: TC3 | C7: Vận động thô | D7: Đi/chạy/bò/bật thành thạo hơn nhà trẻ: giữ thăng bằng khi đổi hướng - tốc độ, tự lên xuống bậc thang không cần bám vịn liên tục, phối hợp tay-chân trong trò chơi vận động nhóm nhỏ. | E7: Vận động linh hoạt, phối hợp nhiều kỹ năng cùng lúc (chạy-né vật cản-bắt bóng); tự điều chỉnh lực/tốc độ phù hợp tình huống chơi. | F7: Thực hiện vận động di chuyển đa dạng, giữ thăng bằng, phối hợp dụng cụ thuần thục. | G7: Trẻ đi thăng bằng trên ghế thể dục cao 30cm không cần cô đỡ. | H7: Tự lực | I7: —
A8: Thể chất | B8: TC4 | C8: Vận động tinh | D8: Thao tác tay tinh hơn: tự cài cúc to, kéo khóa, cắt theo đường cong đơn giản, xâu hạt nhỏ hơn nhà trẻ; phối hợp tay-mắt khi ném/bắt bóng nhỏ. | E8: Thao tác tinh chính xác hơn: cắt theo đường cong phức tạp, gấp giấy nhiều bước, viết nét chữ cái đầu tiên rõ ràng. | F8: Thao tác vật liệu đa dạng, kiểm soát cơ nhỏ, phối hợp tay-mắt; tự phục vụ thành thạo. | G8: Trẻ tự cài cúc áo, cắt hình theo đường viền có sẵn. | H8: Tự lực | I8: —
A9: Thể chất | B9: TC5 | C9: Thực hành ăn uống hợp lý | D9: Tự xúc ăn gọn gàng và ăn hết khẩu phần không cần nhắc (kế thừa từ nhà trẻ); bắt đầu nhận biết món nào thuộc nhóm chất gì khi được hỏi. | E9: Giải thích được vì sao nên ăn đa dạng thực phẩm; tự đề xuất món ăn tốt cho sức khỏe khi được hỏi. | F9: Nhận biết nhóm chất dinh dưỡng; ăn đa dạng, hành vi văn minh trong ăn uống. | G9: Trẻ tự chọn và ăn đủ các nhóm thực phẩm trong bữa ăn tại lớp. | H9: Tự lực | I9: Trách nhiệm
A10: Thể chất | B10: TC6 | C10: Chăm sóc sức khỏe, vệ sinh | D10: Tự thực hiện đủ các bước vệ sinh cá nhân quen thuộc (rửa tay, lau mặt) không cần cô làm cùng, chỉ cần nhắc nhở thời điểm; nhận biết rõ sạch-bẩn. | E10: Chủ động nhắc bạn cùng thực hiện vệ sinh đúng cách; tự nhận biết khi nào cơ thể mình không khỏe và báo cô. | F10: Chủ động, thuần thục vệ sinh cá nhân; hiểu quan hệ vệ sinh-sức khỏe, nhận ra dấu hiệu bệnh. | G10: Trẻ tự giác rửa tay trước ăn không cần nhắc, biết báo cô khi thấy mệt. | H10: Tự lực | I10: Trách nhiệm
A11: Thể chất | B11: TC7 | C11: Đảm bảo an toàn | D11: Tự tránh xa 2-3 tình huống nguy hiểm quen thuộc mà không cần cô nhắc tại chỗ; báo cho cô khi thấy bạn gặp nguy hiểm. | E11: Giải thích được vì sao 1 tình huống nguy hiểm, không chỉ tránh mà còn nhắc/ngăn bạn khi thấy bạn làm sai. | F11: Nhận ra tình huống nguy hiểm và xử lý phù hợp; không đồng tình hành vi mất an toàn. | G11: Trẻ tự tránh xa ổ điện, nhắc bạn không chạy gần cầu thang. | H11: Giải quyết vấn đề, Tự lực | I11: Trách nhiệm
A12: Tình cảm - xã hội | B12: TX1 | C12: Nhận biết về bản thân | D12: Tự giới thiệu đầy đủ họ tên, tuổi, giới tính, sở thích rõ ràng khi có người hỏi, kể được 1-2 điều mình làm tốt. | E12: Kể được điểm mạnh và điều mình đang cố gắng cải thiện; so sánh được sở thích của mình với bạn khác. | F12: Tự nhận diện đặc điểm, sở thích, khả năng riêng của mình. | G12: Trẻ tự giới thiệu về mình và điều mình thích trước lớp. | H12: Tự lực | I12: Trung thực
A13: Tình cảm - xã hội | B13: TX2 | C13: Quản lý bản thân | D13: Tự gọi tên được nhiều cảm xúc (vui, buồn, giận, sợ) không cần cô gợi ý trước; bắt đầu tự trấn tĩnh bằng cách đơn giản (hít thở, tìm đồ chơi yêu thích) khi buồn/giận nhẹ. | E13: Tự áp dụng 1 cách trấn tĩnh phù hợp khi buồn/giận mà không cần cô nhắc; nhận ra cảm xúc của bạn qua nét mặt. | F13: Nhận biết và gọi tên nhiều trạng thái cảm xúc; bước đầu tự điều chỉnh hành vi. | G13: Trẻ tự nói ra cảm xúc của mình và biết chờ đợi khi tức giận. | H13: Tự lực, Thích ứng | I13: —
A14: Tình cảm - xã hội | B14: TX3 | C14: Nhận biết mối quan hệ xã hội | D14: Gọi đúng tên và vai trò của nhiều người xung quanh (không chỉ người thân) như bác bảo vệ, cô cấp dưỡng; hiểu vị trí của mình trong nhóm bạn nhỏ. | E14: Giải thích được vai trò/công việc của một số người trong cộng đồng (bác sĩ, công an...) không chỉ gọi tên. | F14: Nhận biết và ứng xử phù hợp vị trí trong gia đình/trường/lớp/cộng đồng. | G14: Trẻ biết chào đúng cách với cô, ông bà, bạn bè theo từng vai trò. | H14: Giao tiếp, Hợp tác | I14: Tôn trọng
A15: Tình cảm - xã hội | B15: TX4 | C15: Thiết lập và duy trì mối quan hệ xã hội | D15: Chủ động rủ từ 2 bạn trở lên cùng chơi, tự giới thiệu bản thân với bạn mới mà không cần cô làm cầu nối. | E15: Duy trì nhóm bạn chơi ổn định qua nhiều ngày, tự hòa giải mâu thuẫn nhỏ với bạn mà không cần cô can thiệp ngay. | F15: Chủ động thiết lập quan hệ với bạn mới/người lớn; duy trì quan hệ bạn bè ổn định, biết làm hòa. | G15: Trẻ tự làm hòa với bạn sau khi giận nhau, rủ bạn mới cùng chơi. | H15: Giao tiếp, Hợp tác | I15: Yêu thương
... A34: Nghệ thuật | B34: NgT7 | C34: Sáng tạo trong hoạt động kịch/vận động nghệ thuật | D34: Tự nhận 1 vai chơi đơn giản trong trò chơi đóng vai theo nhóm nhỏ, có 1-2 câu thoại tự nghĩ ra. | E34: Tự xây dựng một đoạn tình huống chơi đóng vai có 2-3 nhân vật với lời thoại do nhóm tự nghĩ ra. | F34: Chủ động sáng tạo trong hoạt động kịch, vận động minh họa, phối hợp nhóm. | G34: Trẻ tự nghĩ lời thoại mới khi đóng kịch cùng nhóm bạn. | H34: Hợp tác | I34: —

Sheet MOCPT
A1: MỐC PHÁT TRIỂN 36-72 THÁNG (6 MỐC x 6 THÁNG) | J1: =HYPERLINK("#TRANGCHU!A1","⬅ Về Trang chủ") -> ⬅ Về Trang chủ | K1: =HYPERLINK("#HUONGDAN!A1","📖 Về Hướng dẫn") -> 📖 Về Hướng dẫn
A2: Chia nhỏ tiến trình I→R→M thành 6 mốc để GV chọn hoạt động sát tốc độ thực của trẻ. Mốc 1-2 tương ứng vùng mức I, 3-4 vùng mức R, 5-6 vùng mức M — là mốc GỢI Ý CĂN CHỈNH, không phải dữ liệu đo lường mới.
A3: Lưu ý: nội dung mốc 1,3,5 (đầu giai đoạn) và mốc 2,4,6 (cuối giai đoạn) được nội suy từ đúng 3 mức I/R/M đã có ở sheet KHUNGNL — GV cần quan sát thực tế để hiệu chỉnh thêm.
A5: Mã | B5: Tên năng lực | C5: 36-42th | D5: 42-48th | E5: 48-54th | F5: 54-60th | G5: 60-66th | H5: 66-72th
A6: TC1 | B6: Chủ động tham gia hoạt động thể chất | C6: Chủ động rủ bạn/tự chọn tham gia hoạt động thể chất mà không cần cô rủ trước; | D6: cố gắng hoàn thành dù hơi mệt, chỉ nghỉ khi thực sự cần. | E6: Mới bắt đầu: Tự đặt mục tiêu nhỏ cho bản thân khi vận động (VD: bật xa hơn lần trước) và cố gắng đạt được, ít cần cô động viên giữa chừng. | F6: Ổn định dần: Tự đặt mục tiêu nhỏ cho bản thân khi vận động (VD: bật xa hơn lần trước) và cố gắng đạt được, ít cần cô động viên giữa chừng. | G6: Mới bắt đầu: Chủ động, hào hứng, không bỏ cuộc cho đến khi đạt mục tiêu vận động. | H6: Ổn định dần: Chủ động, hào hứng, không bỏ cuộc cho đến khi đạt mục tiêu vận động.
A7: TC2 | B7: Thích ứng thay đổi vận động/sinh hoạt | C7: Mới bắt đầu: Tự điều chỉnh khi có thay đổi nhỏ, quen thuộc trong giờ vận động/sinh hoạt (đổi chỗ chơi, đổi bạn cùng nhóm) mà không cần cô trấn an nhiều. | D7: Ổn định dần: Tự điều chỉnh khi có thay đổi nhỏ, quen thuộc trong giờ vận động/sinh hoạt (đổi chỗ chơi, đổi bạn cùng nhóm) mà không cần cô trấn an nhiều. | E7: Mới bắt đầu: Thích ứng nhanh với hầu hết thay đổi trong sinh hoạt/vận động, kể cả thay đổi chưa quen nếu được báo trước. | F7: Ổn định dần: Thích ứng nhanh với hầu hết thay đổi trong sinh hoạt/vận động, kể cả thay đổi chưa quen nếu được báo trước. | G7: Chủ động đáp ứng khi có thay đổi hoạt động/sinh hoạt; | H7: dễ hòa nhập môi trường mới.
A8: TC3 | B8: Vận động thô | C8: Mới bắt đầu: Đi/chạy/bò/bật thành thạo hơn nhà trẻ: giữ thăng bằng khi đổi hướng - tốc độ, tự lên xuống bậc thang không cần bám vịn liên tục, phối hợp tay-chân trong trò chơi vận động nhóm nhỏ. | D8: Ổn định dần: Đi/chạy/bò/bật thành thạo hơn nhà trẻ: giữ thăng bằng khi đổi hướng - tốc độ, tự lên xuống bậc thang không cần bám vịn liên tục, phối hợp tay-chân trong trò chơi vận động nhóm nhỏ. | E8: Vận động linh hoạt, phối hợp nhiều kỹ năng cùng lúc (chạy-né vật cản-bắt bóng); | F8: tự điều chỉnh lực/tốc độ phù hợp tình huống chơi. | G8: Mới bắt đầu: Thực hiện vận động di chuyển đa dạng, giữ thăng bằng, phối hợp dụng cụ thuần thục. | H8: Ổn định dần: Thực hiện vận động di chuyển đa dạng, giữ thăng bằng, phối hợp dụng cụ thuần thục.
A9: TC4 | B9: Vận động tinh | C9: Thao tác tay tinh hơn: tự cài cúc to, kéo khóa, cắt theo đường cong đơn giản, xâu hạt nhỏ hơn nhà trẻ; | D9: phối hợp tay-mắt khi ném/bắt bóng nhỏ. | E9: Mới bắt đầu: Thao tác tinh chính xác hơn: cắt theo đường cong phức tạp, gấp giấy nhiều bước, viết nét chữ cái đầu tiên rõ ràng. | F9: Ổn định dần: Thao tác tinh chính xác hơn: cắt theo đường cong phức tạp, gấp giấy nhiều bước, viết nét chữ cái đầu tiên rõ ràng. | G9: Thao tác vật liệu đa dạng, kiểm soát cơ nhỏ, phối hợp tay-mắt; | H9: tự phục vụ thành thạo.
A10: TC5 | B10: Thực hành ăn uống hợp lý | C10: Tự xúc ăn gọn gàng và ăn hết khẩu phần không cần nhắc (kế thừa từ nhà trẻ); | D10: bắt đầu nhận biết món nào thuộc nhóm chất gì khi được hỏi. | E10: Giải thích được vì sao nên ăn đa dạng thực phẩm; | F10: tự đề xuất món ăn tốt cho sức khỏe khi được hỏi. | G10: Nhận biết nhóm chất dinh dưỡng; | H10: ăn đa dạng, hành vi văn minh trong ăn uống.
A11: TC6 | B11: Chăm sóc sức khỏe, vệ sinh | C11: Tự thực hiện đủ các bước vệ sinh cá nhân quen thuộc (rửa tay, lau mặt) không cần cô làm cùng, chỉ cần nhắc nhở thời điểm; | D11: nhận biết rõ sạch-bẩn. | E11: Chủ động nhắc bạn cùng thực hiện vệ sinh đúng cách; | F11: tự nhận biết khi nào cơ thể mình không khỏe và báo cô. | G11: Chủ động, thuần thục vệ sinh cá nhân; | H11: hiểu quan hệ vệ sinh-sức khỏe, nhận ra dấu hiệu bệnh.
A12: TC7 | B12: Đảm bảo an toàn | C12: Tự tránh xa 2-3 tình huống nguy hiểm quen thuộc mà không cần cô nhắc tại chỗ; | D12: báo cho cô khi thấy bạn gặp nguy hiểm. | E12: Mới bắt đầu: Giải thích được vì sao 1 tình huống nguy hiểm, không chỉ tránh mà còn nhắc/ngăn bạn khi thấy bạn làm sai. | F12: Ổn định dần: Giải thích được vì sao 1 tình huống nguy hiểm, không chỉ tránh mà còn nhắc/ngăn bạn khi thấy bạn làm sai. | G12: Nhận ra tình huống nguy hiểm và xử lý phù hợp; | H12: không đồng tình hành vi mất an toàn.
A13: TX1 | B13: Nhận biết về bản thân | C13: Mới bắt đầu: Tự giới thiệu đầy đủ họ tên, tuổi, giới tính, sở thích rõ ràng khi có người hỏi, kể được 1-2 điều mình làm tốt. | D13: Ổn định dần: Tự giới thiệu đầy đủ họ tên, tuổi, giới tính, sở thích rõ ràng khi có người hỏi, kể được 1-2 điều mình làm tốt. | E13: Kể được điểm mạnh và điều mình đang cố gắng cải thiện; | F13: so sánh được sở thích của mình với bạn khác. | G13: Mới bắt đầu: Tự nhận diện đặc điểm, sở thích, khả năng riêng của mình. | H13: Ổn định dần: Tự nhận diện đặc điểm, sở thích, khả năng riêng của mình.
A14: TX2 | B14: Quản lý bản thân | C14: Tự gọi tên được nhiều cảm xúc (vui, buồn, giận, sợ) không cần cô gợi ý trước; | D14: bắt đầu tự trấn tĩnh bằng cách đơn giản (hít thở, tìm đồ chơi yêu thích) khi buồn/giận nhẹ. | E14: Tự áp dụng 1 cách trấn tĩnh phù hợp khi buồn/giận mà không cần cô nhắc; | F14: nhận ra cảm xúc của bạn qua nét mặt. | G14: Nhận biết và gọi tên nhiều trạng thái cảm xúc; | H14: bước đầu tự điều chỉnh hành vi.
A15: TX3 | B15: Nhận biết mối quan hệ xã hội | C15: Gọi đúng tên và vai trò của nhiều người xung quanh (không chỉ người thân) như bác bảo vệ, cô cấp dưỡng; | D15: hiểu vị trí của mình trong nhóm bạn nhỏ. | E15: Mới bắt đầu: Giải thích được vai trò/công việc của một số người trong cộng đồng (bác sĩ, công an...) không chỉ gọi tên. | F15: Ổn định dần: Giải thích được vai trò/công việc của một số người trong cộng đồng (bác sĩ, công an...) không chỉ gọi tên. | G15: Mới bắt đầu: Nhận biết và ứng xử phù hợp vị trí trong gia đình/trường/lớp/cộng đồng. | H15: Ổn định dần: Nhận biết và ứng xử phù hợp vị trí trong gia đình/trường/lớp/cộng đồng.
A16: TX4 | B16: Thiết lập và duy trì mối quan hệ xã hội | C16: Mới bắt đầu: Chủ động rủ từ 2 bạn trở lên cùng chơi, tự giới thiệu bản thân với bạn mới mà không cần cô làm cầu nối. | D16: Ổn định dần: Chủ động rủ từ 2 bạn trở lên cùng chơi, tự giới thiệu bản thân với bạn mới mà không cần cô làm cầu nối. | E16: Mới bắt đầu: Duy trì nhóm bạn chơi ổn định qua nhiều ngày, tự hòa giải mâu thuẫn nhỏ với bạn mà không cần cô can thiệp ngay. | F16: Ổn định dần: Duy trì nhóm bạn chơi ổn định qua nhiều ngày, tự hòa giải mâu thuẫn nhỏ với bạn mà không cần cô can thiệp ngay. | G16: Chủ động thiết lập quan hệ với bạn mới/người lớn; | H16: duy trì quan hệ bạn bè ổn định, biết làm hòa.
... A35: NgT7 | B35: Sáng tạo trong hoạt động kịch/vận động nghệ thuật | C35: Mới bắt đầu: Tự nhận 1 vai chơi đơn giản trong trò chơi đóng vai theo nhóm nhỏ, có 1-2 câu thoại tự nghĩ ra. | D35: Ổn định dần: Tự nhận 1 vai chơi đơn giản trong trò chơi đóng vai theo nhóm nhỏ, có 1-2 câu thoại tự nghĩ ra. | E35: Mới bắt đầu: Tự xây dựng một đoạn tình huống chơi đóng vai có 2-3 nhân vật với lời thoại do nhóm tự nghĩ ra. | F35: Ổn định dần: Tự xây dựng một đoạn tình huống chơi đóng vai có 2-3 nhân vật với lời thoại do nhóm tự nghĩ ra. | G35: Mới bắt đầu: Chủ động sáng tạo trong hoạt động kịch, vận động minh họa, phối hợp nhóm. | H35: Ổn định dần: Chủ động sáng tạo trong hoạt động kịch, vận động minh họa, phối hợp nhóm.

Sheet MATRANYCCD
A1: MA TRẬN YÊU CẦU CẦN ĐẠT (YCCĐ) — ĐỐI CHIẾU QĐ 388 VÀ QĐ 4222 | H1: =HYPERLINK("#TRANGCHU!A1","⬅ Về Trang chủ") -> ⬅ Về Trang chủ | I1: =HYPERLINK("#HUONGDAN!A1","📖 Về Hướng dẫn") -> 📖 Về Hướng dẫn
A2: QĐ 4222 (Bộ chuẩn phát triển trẻ 5 tuổi) chỉ áp dụng cho MGL. MGB/MGN xây dựng THUẦN theo QĐ 388, không có đối chiếu 4222 tương ứng — đây là đặc điểm của hệ thống, không phải thiếu sót.
A4: Mã | B4: Tên năng lực | C4: YCCĐ 388 (mức M - đích chung 5-6 tuổi) | D4: Đối chiếu CS QĐ 4222 (chỉ MGL) | E4: Áp dụng độ tuổi | F4: Ghi chú
A5: TC1 | B5: Chủ động tham gia hoạt động thể chất | C5: Chủ động, hào hứng, không bỏ cuộc cho đến khi đạt mục tiêu vận động. | D5: Có đối chiếu CS-4222 (xem chi tiết trong Mục tiêu năm học 5-6 tuổi chuẩn hóa) | E5: MGB (I) · MGN (R) · MGL (M) | F5: Áp dụng cả 3 độ tuổi theo mức I/R/M tương ứng (xem sheet KHUNGNL)
A6: TC2 | B6: Thích ứng thay đổi vận động/sinh hoạt | C6: Chủ động đáp ứng khi có thay đổi hoạt động/sinh hoạt; dễ hòa nhập môi trường mới. | D6: Có đối chiếu CS-4222 (xem chi tiết trong Mục tiêu năm học 5-6 tuổi chuẩn hóa) | E6: MGB (I) · MGN (R) · MGL (M) | F6: Áp dụng cả 3 độ tuổi theo mức I/R/M tương ứng (xem sheet KHUNGNL)
A7: TC3 | B7: Vận động thô | C7: Thực hiện vận động di chuyển đa dạng, giữ thăng bằng, phối hợp dụng cụ thuần thục. | D7: Có đối chiếu CS-4222 (xem chi tiết trong Mục tiêu năm học 5-6 tuổi chuẩn hóa) | E7: MGB (I) · MGN (R) · MGL (M) | F7: Áp dụng cả 3 độ tuổi theo mức I/R/M tương ứng (xem sheet KHUNGNL)
A8: TC4 | B8: Vận động tinh | C8: Thao tác vật liệu đa dạng, kiểm soát cơ nhỏ, phối hợp tay-mắt; tự phục vụ thành thạo. | D8: Có đối chiếu CS-4222 (xem chi tiết trong Mục tiêu năm học 5-6 tuổi chuẩn hóa) | E8: MGB (I) · MGN (R) · MGL (M) | F8: Áp dụng cả 3 độ tuổi theo mức I/R/M tương ứng (xem sheet KHUNGNL)
A9: TC5 | B9: Thực hành ăn uống hợp lý | C9: Nhận biết nhóm chất dinh dưỡng; ăn đa dạng, hành vi văn minh trong ăn uống. | D9: Có đối chiếu CS-4222 (xem chi tiết trong Mục tiêu năm học 5-6 tuổi chuẩn hóa) | E9: MGB (I) · MGN (R) · MGL (M) | F9: Áp dụng cả 3 độ tuổi theo mức I/R/M tương ứng (xem sheet KHUNGNL)
A10: TC6 | B10: Chăm sóc sức khỏe, vệ sinh | C10: Chủ động, thuần thục vệ sinh cá nhân; hiểu quan hệ vệ sinh-sức khỏe, nhận ra dấu hiệu bệnh. | D10: Có đối chiếu CS-4222 (xem chi tiết trong Mục tiêu năm học 5-6 tuổi chuẩn hóa) | E10: MGB (I) · MGN (R) · MGL (M) | F10: Áp dụng cả 3 độ tuổi theo mức I/R/M tương ứng (xem sheet KHUNGNL)
A11: TC7 | B11: Đảm bảo an toàn | C11: Nhận ra tình huống nguy hiểm và xử lý phù hợp; không đồng tình hành vi mất an toàn. | D11: Có đối chiếu CS-4222 (xem chi tiết trong Mục tiêu năm học 5-6 tuổi chuẩn hóa) | E11: MGB (I) · MGN (R) · MGL (M) | F11: Áp dụng cả 3 độ tuổi theo mức I/R/M tương ứng (xem sheet KHUNGNL)
A12: TX1 | B12: Nhận biết về bản thân | C12: Tự nhận diện đặc điểm, sở thích, khả năng riêng của mình. | D12: Có đối chiếu CS-4222 (xem chi tiết trong Mục tiêu năm học 5-6 tuổi chuẩn hóa) | E12: MGB (I) · MGN (R) · MGL (M) | F12: Áp dụng cả 3 độ tuổi theo mức I/R/M tương ứng (xem sheet KHUNGNL)
A13: TX2 | B13: Quản lý bản thân | C13: Nhận biết và gọi tên nhiều trạng thái cảm xúc; bước đầu tự điều chỉnh hành vi. | D13: Có đối chiếu CS-4222 (xem chi tiết trong Mục tiêu năm học 5-6 tuổi chuẩn hóa) | E13: MGB (I) · MGN (R) · MGL (M) | F13: Áp dụng cả 3 độ tuổi theo mức I/R/M tương ứng (xem sheet KHUNGNL)
A14: TX3 | B14: Nhận biết mối quan hệ xã hội | C14: Nhận biết và ứng xử phù hợp vị trí trong gia đình/trường/lớp/cộng đồng. | D14: Có đối chiếu CS-4222 (xem chi tiết trong Mục tiêu năm học 5-6 tuổi chuẩn hóa) | E14: MGB (I) · MGN (R) · MGL (M) | F14: Áp dụng cả 3 độ tuổi theo mức I/R/M tương ứng (xem sheet KHUNGNL)
A15: TX4 | B15: Thiết lập và duy trì mối quan hệ xã hội | C15: Chủ động thiết lập quan hệ với bạn mới/người lớn; duy trì quan hệ bạn bè ổn định, biết làm hòa. | D15: Có đối chiếu CS-4222 (xem chi tiết trong Mục tiêu năm học 5-6 tuổi chuẩn hóa) | E15: MGB (I) · MGN (R) · MGL (M) | F15: Áp dụng cả 3 độ tuổi theo mức I/R/M tương ứng (xem sheet KHUNGNL)
... A34: NgT7 | B34: Sáng tạo trong hoạt động kịch/vận động nghệ thuật | C34: Chủ động sáng tạo trong hoạt động kịch, vận động minh họa, phối hợp nhóm. | D34: Có đối chiếu CS-4222 (xem chi tiết trong Mục tiêu năm học 5-6 tuổi chuẩn hóa) | E34: MGB (I) · MGN (R) · MGL (M) | F34: Áp dụng cả 3 độ tuổi theo mức I/R/M tương ứng (xem sheet KHUNGNL)

Sheet KHNAM_3_4T
A1: KẾ HOẠCH GIÁO DỤC NĂM HỌC — MẪU GIÁO BÉ 3-4 TUỔI | E1: =HYPERLINK("#TRANGCHU!A1","⬅ Về Trang chủ") -> ⬅ Về Trang chủ | F1: =HYPERLINK("#HUONGDAN!A1","📖 Về Hướng dẫn") -> 📖 Về Hướng dẫn
A2: Mức I - Hình thành
A4: I. ĐẶC ĐIỂM PHÁT TRIỂN
A5: Tư duy trực quan-hành động chủ đạo; tập trung ngắn (5-10 phút); muốn tự lập nhưng khả năng còn hạn chế; chơi cạnh bạn (song song) là chủ yếu; cần hỗ trợ trực tiếp phần lớn hoạt động tự phục vụ.
A7: II. MỤC TIÊU NĂM HỌC (5 LĨNH VỰC, MỨC I - Hình thành)
A8: Lĩnh vực | B8: Mã | C8: Mục tiêu năm học
A9: Thể chất | B9: TC1 | C9: Chủ động tham gia hoạt động thể chất: Chủ động rủ bạn/tự chọn tham gia hoạt động thể chất mà không cần cô rủ trước; cố gắng hoàn thành dù hơi mệt, chỉ nghỉ khi thực sự cần.
A10: Thể chất | B10: TC2 | C10: Thích ứng thay đổi vận động/sinh hoạt: Tự điều chỉnh khi có thay đổi nhỏ, quen thuộc trong giờ vận động/sinh hoạt (đổi chỗ chơi, đổi bạn cùng nhóm) mà không cần cô trấn an nhiều.
A11: Thể chất | B11: TC3 | C11: Vận động thô: Đi/chạy/bò/bật thành thạo hơn nhà trẻ: giữ thăng bằng khi đổi hướng - tốc độ, tự lên xuống bậc thang không cần bám vịn liên tục, phối hợp tay-chân trong trò chơi vận động nhóm nhỏ.
A12: Thể chất | B12: TC4 | C12: Vận động tinh: Thao tác tay tinh hơn: tự cài cúc to, kéo khóa, cắt theo đường cong đơn giản, xâu hạt nhỏ hơn nhà trẻ; phối hợp tay-mắt khi ném/bắt bóng nhỏ.
A13: Thể chất | B13: TC5 | C13: Thực hành ăn uống hợp lý: Tự xúc ăn gọn gàng và ăn hết khẩu phần không cần nhắc (kế thừa từ nhà trẻ); bắt đầu nhận biết món nào thuộc nhóm chất gì khi được hỏi.
A14: Thể chất | B14: TC6 | C14: Chăm sóc sức khỏe, vệ sinh: Tự thực hiện đủ các bước vệ sinh cá nhân quen thuộc (rửa tay, lau mặt) không cần cô làm cùng, chỉ cần nhắc nhở thời điểm; nhận biết rõ sạch-bẩn.
A15: Thể chất | B15: TC7 | C15: Đảm bảo an toàn: Tự tránh xa 2-3 tình huống nguy hiểm quen thuộc mà không cần cô nhắc tại chỗ; báo cho cô khi thấy bạn gặp nguy hiểm.
A16: Tình cảm - xã hội | B16: TX1 | C16: Nhận biết về bản thân: Tự giới thiệu đầy đủ họ tên, tuổi, giới tính, sở thích rõ ràng khi có người hỏi, kể được 1-2 điều mình làm tốt.
A17: Tình cảm - xã hội | B17: TX2 | C17: Quản lý bản thân: Tự gọi tên được nhiều cảm xúc (vui, buồn, giận, sợ) không cần cô gợi ý trước; bắt đầu tự trấn tĩnh bằng cách đơn giản (hít thở, tìm đồ chơi yêu thích) khi buồn/giận nhẹ.
A18: Tình cảm - xã hội | B18: TX3 | C18: Nhận biết mối quan hệ xã hội: Gọi đúng tên và vai trò của nhiều người xung quanh (không chỉ người thân) như bác bảo vệ, cô cấp dưỡng; hiểu vị trí của mình trong nhóm bạn nhỏ.
A19: Tình cảm - xã hội | B19: TX4 | C19: Thiết lập và duy trì mối quan hệ xã hội: Chủ động rủ từ 2 bạn trở lên cùng chơi, tự giới thiệu bản thân với bạn mới mà không cần cô làm cầu nối.
... A38: Nghệ thuật | B38: NgT7 | C38: Sáng tạo trong hoạt động kịch/vận động nghệ thuật: Tự nhận 1 vai chơi đơn giản trong trò chơi đóng vai theo nhóm nhỏ, có 1-2 câu thoại tự nghĩ ra.
A40: III. PHÂN PHỐI CHỦ ĐỀ 35 TUẦN
A41: Tuần | B41: Chủ đề lớn
A42: 1-3 | B42: Trường mầm non - Lớp học của bé
A43: 4-6 | B43: Bé là ai - Cơ thể và giác quan
A44: 7-10 | B44: Gia đình yêu thương (gồm dinh dưỡng)
A45: 11-14 | B45: Nghề nghiệp quen thuộc quanh bé
A46: 15-19 | B46: Thế giới động vật gần gũi
A47: 20-23 | B47: Thế giới thực vật - Tết cổ truyền
A48: 24-25 | B48: Bé và phương tiện giao thông
A49: 26-29 | B49: Nước và hiện tượng tự nhiên
A50: 30-33 | B50: Quê hương - Đất nước - Bác Hồ
A51: 34-35 | B51: Bé lớn lên mỗi ngày - Mùa hè vui
A53: IV. HOẠT ĐỘNG TRỌNG TÂM
A54: • Trò chơi vận động dụng cụ quen thuộc, thể dục sáng theo nhạc.
A55: • Góc phân vai (gia đình, bán hàng), góc xây dựng khối to, góc nghệ thuật vẽ/nặn tự do.
A56: • STEAM đơn giản: quan sát-thử nghiệm (vật nổi/chìm, cây lớn lên) - không yêu cầu ghi chép.
A57: • SEL: nhận thức bản thân qua góc gương soi; nhận biết cảm xúc cơ bản qua tranh.
A58: • Ngoài trời: dạo quanh khu vực quen thuộc của trường có cô đi cùng.
A60: V. ĐÁNH GIÁ
A61: Đánh giá vì sự phát triển của trẻ: quan sát, minh chứng, không kiểm tra kiến thức, không so sánh. Dùng RUBRIC + BANGKIEMLOP + NHATKYQUANSAT.
A63: VI. PHỐI HỢP CHA MẸ TRẺ
A64: Trao đổi hằng ngày lúc đón-trả trẻ; dùng PHIEUTRAODOI định kỳ theo chủ đề/tháng; mời phụ huynh tham gia hoạt động trải nghiệm phù hợp.

Sheet KHNAM_4_5T
A1: KẾ HOẠCH GIÁO DỤC NĂM HỌC — MẪU GIÁO NHỠ 4-5 TUỔI | E1: =HYPERLINK("#TRANGCHU!A1","⬅ Về Trang chủ") -> ⬅ Về Trang chủ | F1: =HYPERLINK("#HUONGDAN!A1","📖 Về Hướng dẫn") -> 📖 Về Hướng dẫn
A2: Mức R - Củng cố
A4: I. ĐẶC ĐIỂM PHÁT TRIỂN
A5: Tư duy trực quan-hình tượng phát triển mạnh; tập trung 10-15 phút; chuyển từ chơi cạnh bạn sang chơi cùng nhóm nhỏ; chủ động hơn trong tự phục vụ; bắt đầu hợp tác, thử nghiệm và chia sẻ ý tưởng trong tình huống quen thuộc.
A7: II. MỤC TIÊU NĂM HỌC (5 LĨNH VỰC, MỨC R - Củng cố)
A8: Lĩnh vực | B8: Mã | C8: Mục tiêu năm học
A9: Thể chất | B9: TC1 | C9: Chủ động tham gia hoạt động thể chất: Tự đặt mục tiêu nhỏ cho bản thân khi vận động (VD: bật xa hơn lần trước) và cố gắng đạt được, ít cần cô động viên giữa chừng.
A10: Thể chất | B10: TC2 | C10: Thích ứng thay đổi vận động/sinh hoạt: Thích ứng nhanh với hầu hết thay đổi trong sinh hoạt/vận động, kể cả thay đổi chưa quen nếu được báo trước.
A11: Thể chất | B11: TC3 | C11: Vận động thô: Vận động linh hoạt, phối hợp nhiều kỹ năng cùng lúc (chạy-né vật cản-bắt bóng); tự điều chỉnh lực/tốc độ phù hợp tình huống chơi.
A12: Thể chất | B12: TC4 | C12: Vận động tinh: Thao tác tinh chính xác hơn: cắt theo đường cong phức tạp, gấp giấy nhiều bước, viết nét chữ cái đầu tiên rõ ràng.
A13: Thể chất | B13: TC5 | C13: Thực hành ăn uống hợp lý: Giải thích được vì sao nên ăn đa dạng thực phẩm; tự đề xuất món ăn tốt cho sức khỏe khi được hỏi.
A14: Thể chất | B14: TC6 | C14: Chăm sóc sức khỏe, vệ sinh: Chủ động nhắc bạn cùng thực hiện vệ sinh đúng cách; tự nhận biết khi nào cơ thể mình không khỏe và báo cô.
A15: Thể chất | B15: TC7 | C15: Đảm bảo an toàn: Giải thích được vì sao 1 tình huống nguy hiểm, không chỉ tránh mà còn nhắc/ngăn bạn khi thấy bạn làm sai.
A16: Tình cảm - xã hội | B16: TX1 | C16: Nhận biết về bản thân: Kể được điểm mạnh và điều mình đang cố gắng cải thiện; so sánh được sở thích của mình với bạn khác.
A17: Tình cảm - xã hội | B17: TX2 | C17: Quản lý bản thân: Tự áp dụng 1 cách trấn tĩnh phù hợp khi buồn/giận mà không cần cô nhắc; nhận ra cảm xúc của bạn qua nét mặt.
A18: Tình cảm - xã hội | B18: TX3 | C18: Nhận biết mối quan hệ xã hội: Giải thích được vai trò/công việc của một số người trong cộng đồng (bác sĩ, công an...) không chỉ gọi tên.
A19: Tình cảm - xã hội | B19: TX4 | C19: Thiết lập và duy trì mối quan hệ xã hội: Duy trì nhóm bạn chơi ổn định qua nhiều ngày, tự hòa giải mâu thuẫn nhỏ với bạn mà không cần cô can thiệp ngay.
... A38: Nghệ thuật | B38: NgT7 | C38: Sáng tạo trong hoạt động kịch/vận động nghệ thuật: Tự xây dựng một đoạn tình huống chơi đóng vai có 2-3 nhân vật với lời thoại do nhóm tự nghĩ ra.
A40: III. PHÂN PHỐI CHỦ ĐỀ 35 TUẦN
A41: Tuần | B41: Chủ đề lớn
A42: 1-3 | B42: Trường mầm non - Lớp học của bé
A43: 4-6 | B43: Bé là ai - Cơ thể và giác quan
A44: 7-10 | B44: Gia đình yêu thương (gồm dinh dưỡng)
A45: 11-14 | B45: Nghề nghiệp quen thuộc quanh bé
A46: 15-19 | B46: Thế giới động vật gần gũi
A47: 20-23 | B47: Thế giới thực vật - Tết cổ truyền
A48: 24-25 | B48: Bé và phương tiện giao thông
A49: 26-29 | B49: Nước và hiện tượng tự nhiên
A50: 30-33 | B50: Quê hương - Đất nước - Bác Hồ
A51: 34-35 | B51: Bé lớn lên mỗi ngày - Mùa hè vui
A53: IV. HOẠT ĐỘNG TRỌNG TÂM
A54: • Trò chơi vận động nhóm nhỏ có luật đơn giản; góc phân vai có phân công vai rõ hơn.
A55: • Góc xây dựng: công trình nhóm 2-3 trẻ, khuyến khích bàn bạc trước khi làm.
A56: • STEAM: thử nghiệm nhóm nhỏ (vật nổi-chìm, nam châm) - dự đoán trước, so sánh kết quả.
A57: • SEL: giới thiệu sở thích trước nhóm; hoạt động cặp đôi chia sẻ vật liệu; bắt đầu ra quyết định đơn giản.
A58: • Ngoài trời: quan sát nhóm nhỏ, khuyến khích mô tả và so sánh với bạn.
A60: V. ĐÁNH GIÁ
A61: Đánh giá vì sự phát triển của trẻ: quan sát, minh chứng, không kiểm tra kiến thức, không so sánh. Dùng RUBRIC + BANGKIEMLOP + NHATKYQUANSAT.
A63: VI. PHỐI HỢP CHA MẸ TRẺ
A64: Trao đổi hằng ngày lúc đón-trả trẻ; dùng PHIEUTRAODOI định kỳ theo chủ đề/tháng; mời phụ huynh tham gia hoạt động trải nghiệm phù hợp.

Sheet KHNAM_5_6T
A1: KẾ HOẠCH GIÁO DỤC NĂM HỌC — MẪU GIÁO LỚN 5-6 TUỔI | E1: =HYPERLINK("#TRANGCHU!A1","⬅ Về Trang chủ") -> ⬅ Về Trang chủ | F1: =HYPERLINK("#HUONGDAN!A1","📖 Về Hướng dẫn") -> 📖 Về Hướng dẫn
A2: Mức M - Thành thạo (đối chiếu QĐ 4222)
A4: I. ĐẶC ĐIỂM PHÁT TRIỂN
A5: Tư duy trực quan-sơ đồ bắt đầu hình thành; tập trung 15-25 phút; chủ động, tự tin trình bày và bảo vệ ý tưởng; hợp tác nhóm ổn định; sẵn sàng thử-sai-cải tiến theo quy trình; chuẩn bị tâm thế vào lớp 1.
A7: II. MỤC TIÊU NĂM HỌC (5 LĨNH VỰC, MỨC M - Thành thạo)
A8: Lĩnh vực | B8: Mã | C8: Mục tiêu năm học
A9: Thể chất | B9: TC1 | C9: Chủ động tham gia hoạt động thể chất: Chủ động, hào hứng, không bỏ cuộc cho đến khi đạt mục tiêu vận động.
A10: Thể chất | B10: TC2 | C10: Thích ứng thay đổi vận động/sinh hoạt: Chủ động đáp ứng khi có thay đổi hoạt động/sinh hoạt; dễ hòa nhập môi trường mới.
A11: Thể chất | B11: TC3 | C11: Vận động thô: Thực hiện vận động di chuyển đa dạng, giữ thăng bằng, phối hợp dụng cụ thuần thục.
A12: Thể chất | B12: TC4 | C12: Vận động tinh: Thao tác vật liệu đa dạng, kiểm soát cơ nhỏ, phối hợp tay-mắt; tự phục vụ thành thạo.
A13: Thể chất | B13: TC5 | C13: Thực hành ăn uống hợp lý: Nhận biết nhóm chất dinh dưỡng; ăn đa dạng, hành vi văn minh trong ăn uống.
A14: Thể chất | B14: TC6 | C14: Chăm sóc sức khỏe, vệ sinh: Chủ động, thuần thục vệ sinh cá nhân; hiểu quan hệ vệ sinh-sức khỏe, nhận ra dấu hiệu bệnh.
A15: Thể chất | B15: TC7 | C15: Đảm bảo an toàn: Nhận ra tình huống nguy hiểm và xử lý phù hợp; không đồng tình hành vi mất an toàn.
A16: Tình cảm - xã hội | B16: TX1 | C16: Nhận biết về bản thân: Tự nhận diện đặc điểm, sở thích, khả năng riêng của mình.
A17: Tình cảm - xã hội | B17: TX2 | C17: Quản lý bản thân: Nhận biết và gọi tên nhiều trạng thái cảm xúc; bước đầu tự điều chỉnh hành vi.
A18: Tình cảm - xã hội | B18: TX3 | C18: Nhận biết mối quan hệ xã hội: Nhận biết và ứng xử phù hợp vị trí trong gia đình/trường/lớp/cộng đồng.
A19: Tình cảm - xã hội | B19: TX4 | C19: Thiết lập và duy trì mối quan hệ xã hội: Chủ động thiết lập quan hệ với bạn mới/người lớn; duy trì quan hệ bạn bè ổn định, biết làm hòa.
... A38: Nghệ thuật | B38: NgT7 | C38: Sáng tạo trong hoạt động kịch/vận động nghệ thuật: Chủ động sáng tạo trong hoạt động kịch, vận động minh họa, phối hợp nhóm.
A40: III. PHÂN PHỐI CHỦ ĐỀ 35 TUẦN
A41: Tuần | B41: Chủ đề lớn
A42: 1-3 | B42: Trường mầm non - Lớp học của bé
A43: 4-6 | B43: Bé là ai - Cơ thể và giác quan
A44: 7-10 | B44: Gia đình yêu thương (gồm dinh dưỡng)
A45: 11-14 | B45: Nghề nghiệp quen thuộc quanh bé
A46: 15-19 | B46: Thế giới động vật gần gũi
A47: 20-23 | B47: Thế giới thực vật - Tết cổ truyền
A48: 24-25 | B48: Bé và phương tiện giao thông
A49: 26-29 | B49: Nước và hiện tượng tự nhiên
A50: 30-33 | B50: Quê hương - Đất nước - Bác Hồ
A51: 34-35 | B51: Bé lớn lên mỗi ngày - Mùa hè vui
A53: IV. HOẠT ĐỘNG TRỌNG TÂM
A54: • Dự án STEAM theo quy trình EDP đầy đủ: Hỏi - Tưởng tượng - Lập kế hoạch - Sáng tạo - Chia sẻ/Cải tiến.
A55: • Góc xây dựng/dự án nhóm phức tạp hơn, trẻ tự phân công và giải quyết mâu thuẫn.
A56: • SEL: ra quyết định có trách nhiệm (chọn và bảo vệ lựa chọn); thấu cảm qua thảo luận tình huống.
A57: • Hoạt động chuẩn bị vào lớp 1: làm quen nề nếp học tập, chữ viết, con số ở mức sẵn sàng.
A58: • Trải nghiệm cộng đồng, tham quan thực tế gắn chủ đề quê hương - đất nước.
A60: V. ĐÁNH GIÁ
A61: Đánh giá vì sự phát triển của trẻ: quan sát, minh chứng, không kiểm tra kiến thức, không so sánh. Dùng RUBRIC + BANGKIEMLOP + NHATKYQUANSAT.
A63: VI. PHỐI HỢP CHA MẸ TRẺ
A64: Trao đổi hằng ngày lúc đón-trả trẻ; dùng PHIEUTRAODOI định kỳ theo chủ đề/tháng; mời phụ huynh tham gia hoạt động trải nghiệm phù hợp.

Sheet PHIENCHE
A1: PHIÊN CHẾ 35 TUẦN CHUNG — MẪU GIÁO 3-6 TUỔI | K1: =HYPERLINK("#TRANGCHU!A1","⬅ Về Trang chủ") -> ⬅ Về Trang chủ | L1: =HYPERLINK("#HUONGDAN!A1","📖 Về Hướng dẫn") -> 📖 Về Hướng dẫn
A2: Nhịp tuần lấy theo MGB/MGN (đã khớp tự nhiên), gộp tuần dinh dưỡng vào Gia đình, đồng bộ khối Nghề nghiệp (chứa tuần 20/11) cho cả 3 khối. Chủ đề nhánh là GỢI Ý — trường/địa phương có thể điều chỉnh.
A4: Tuần | B4: Giai đoạn | C4: Chủ đề lớn | D4: Chủ đề nhánh (gợi ý) | E4: Trục năng lực | F4: 3-4 tuổi | G4: 4-5 tuổi | H4: 5-6 tuổi | I4: Minh chứng
A5: 1 | B5: Hình thành | C5: Trường mầm non - Lớp học của bé | D5: Trường mầm non của bé | E5: Tự lực, Thích ứng, Giao tiếp, Hợp tác | F5: Chủ động tham gia hoạt động thể chất: Hào hứng tham gia khi cô rủ/làm cùng; có thể bỏ giữa chừng nếu mệt/chán. | G5: Chủ động tham gia hoạt động thể chất: Chủ động tham gia phần lớn hoạt động, ít cần nhắc; cố gắng hoàn thành khi hơi khó. | H5: Chủ động tham gia hoạt động thể chất: Chủ động, hào hứng, không bỏ cuộc cho đến khi đạt mục tiêu vận động. | I5: Trẻ tự giác xếp hàng tập thể dục, kiên trì hoàn thành bài tập dù khó.
A6: 2 | B6: Hình thành | C6: Trường mầm non - Lớp học của bé | D6: Lớp học của bé | E6: Tự lực, Thích ứng, Giao tiếp, Hợp tác | F6: Chủ động tham gia hoạt động thể chất: Hào hứng tham gia khi cô rủ/làm cùng; có thể bỏ giữa chừng nếu mệt/chán. | G6: Chủ động tham gia hoạt động thể chất: Chủ động tham gia phần lớn hoạt động, ít cần nhắc; cố gắng hoàn thành khi hơi khó. | H6: Chủ động tham gia hoạt động thể chất: Chủ động, hào hứng, không bỏ cuộc cho đến khi đạt mục tiêu vận động. | I6: Trẻ tự giác xếp hàng tập thể dục, kiên trì hoàn thành bài tập dù khó.
A7: 3 | B7: Hình thành | C7: Trường mầm non - Lớp học của bé | D7: Cơ thể của bé | E7: Tự lực, Giải quyết vấn đề | F7: Vận động thô: Đi/chạy đường ngắn có cô cầm tay; giữ thăng bằng 1-2 giây có đỡ. | G7: Vận động thô: Đi/chạy/bò/ném khá thành thạo với khoảng cách trung bình, ít cần hỗ trợ. | H7: Vận động thô: Thực hiện vận động di chuyển đa dạng, giữ thăng bằng, phối hợp dụng cụ thuần thục. | I7: Trẻ đi thăng bằng trên ghế thể dục cao 30cm không cần cô đỡ.
A8: 4 | B8: Hình thành | C8: Bé là ai - Cơ thể và giác quan | D8: Bé cần gì để khỏe mạnh | E8: Tự lực, Giải quyết vấn đề | F8: Thực hành ăn uống hợp lý: Gọi tên 1-2 món quen thuộc; bắt đầu tự xúc ăn, cần hỗ trợ một phần. | G8: Thực hành ăn uống hợp lý: Kể tên nhiều loại thực phẩm; ăn đa dạng hơn, ít kén chọn. | H8: Thực hành ăn uống hợp lý: Nhận biết nhóm chất dinh dưỡng; ăn đa dạng, hành vi văn minh trong ăn uống. | I8: Trẻ tự chọn và ăn đủ các nhóm thực phẩm trong bữa ăn tại lớp.
A9: 5 | B9: Hình thành | C9: Bé là ai - Cơ thể và giác quan | D9: Cảm xúc của bé | E9: Tự lực, Thích ứng, Giao tiếp | F9: Quản lý bản thân: Nhận biết 1-2 cảm xúc cơ bản (vui/buồn) qua tranh khi cô chỉ. | G9: Quản lý bản thân: Gọi tên được nhiều cảm xúc hơn; bắt đầu tự điều chỉnh khi được nhắc. | H9: Quản lý bản thân: Nhận biết và gọi tên nhiều trạng thái cảm xúc; bước đầu tự điều chỉnh hành vi. | I9: Trẻ tự nói ra cảm xúc của mình và biết chờ đợi khi tức giận.
A10: 6 | B10: Hình thành | C10: Bé là ai - Cơ thể và giác quan | D10: Những người thân trong gia đình | E10: Tự lực, Giao tiếp, Hợp tác | F10: Nhận biết về bản thân: Nói tên, tuổi, giới tính khi được hỏi trực tiếp. | G10: Nhận biết về bản thân: Kể được sở thích, khả năng đơn giản của bản thân. | H10: Nhận biết về bản thân: Tự nhận diện đặc điểm, sở thích, khả năng riêng của mình. | I10: Trẻ tự giới thiệu về mình và điều mình thích trước lớp.
A11: 7 | B11: Hình thành | C11: Gia đình yêu thương (gồm dinh dưỡng, chăm sóc) | D11: Ngôi nhà của bé | E11: Tự lực, Giải quyết vấn đề | F11: Vận động thô: Đi/chạy đường ngắn có cô cầm tay; giữ thăng bằng 1-2 giây có đỡ. | G11: Vận động thô: Đi/chạy/bò/ném khá thành thạo với khoảng cách trung bình, ít cần hỗ trợ. | H11: Vận động thô: Thực hiện vận động di chuyển đa dạng, giữ thăng bằng, phối hợp dụng cụ thuần thục. | I11: Trẻ đi thăng bằng trên ghế thể dục cao 30cm không cần cô đỡ.
A12: 8 | B12: Hình thành | C12: Gia đình yêu thương (gồm dinh dưỡng, chăm sóc) | D12: Đồ dùng trong gia đình | E12: Giải quyết vấn đề, Tự lực | F12: Hiểu biết ban đầu về thế giới xung quanh: Gọi tên 1-2 đặc điểm nổi bật của sự vật quen thuộc. | G12: Hiểu biết ban đầu về thế giới xung quanh: Mô tả một vài đặc điểm/thay đổi đơn giản của sự vật, hiện tượng. | H12: Hiểu biết ban đầu về thế giới xung quanh: Mô tả đặc điểm/tính chất/sự thay đổi của con người, sự vật, hiện tượng xung quanh. | I12: Trẻ mô tả được quá trình cây lớn lên qua các giai đoạn quan sát.
A13: 9 | B13: Hình thành | C13: Gia đình yêu thương (gồm dinh dưỡng, chăm sóc) | D13: Bữa ăn và giấc ngủ của bé | E13: Tự lực, Thích ứng | F13: Thực hành ăn uống hợp lý: Gọi tên 1-2 món quen thuộc; bắt đầu tự xúc ăn, cần hỗ trợ một phần. | G13: Thực hành ăn uống hợp lý: Kể tên nhiều loại thực phẩm; ăn đa dạng hơn, ít kén chọn. | H13: Thực hành ăn uống hợp lý: Nhận biết nhóm chất dinh dưỡng; ăn đa dạng, hành vi văn minh trong ăn uống. | I13: Trẻ tự chọn và ăn đủ các nhóm thực phẩm trong bữa ăn tại lớp.
A14: 10 | B14: Hình thành | C14: Gia đình yêu thương (gồm dinh dưỡng, chăm sóc) | D14: Nghề của bố, của mẹ | E14: Giao tiếp, Hợp tác | F14: Nhận biết mối quan hệ xã hội: Nhận biết người thân trong gia đình qua hình ảnh. | G14: Nhận biết mối quan hệ xã hội: Nhận biết vai trò của một số người xung quanh (cô giáo, bạn bè). | H14: Nhận biết mối quan hệ xã hội: Nhận biết và ứng xử phù hợp vị trí trong gia đình/trường/lớp/cộng đồng. | I14: Trẻ biết chào đúng cách với cô, ông bà, bạn bè theo từng vai trò.
A15: 11 | B15: Hình thành | C15: Nghề nghiệp quen thuộc quanh bé | D15: Cô giáo của bé (20/11) | E15: Giao tiếp, Hợp tác | F15: Nhận biết mối quan hệ xã hội: Nhận biết người thân trong gia đình qua hình ảnh. | G15: Nhận biết mối quan hệ xã hội: Nhận biết vai trò của một số người xung quanh (cô giáo, bạn bè). | H15: Nhận biết mối quan hệ xã hội: Nhận biết và ứng xử phù hợp vị trí trong gia đình/trường/lớp/cộng đồng. | I15: Trẻ biết chào đúng cách với cô, ông bà, bạn bè theo từng vai trò.
A16: 12 | B16: Hình thành | C16: Nghề nghiệp quen thuộc quanh bé | D16: Một số nghề trong xã hội | E16: Giao tiếp, Hợp tác | F16: Nhận biết mối quan hệ xã hội: Nhận biết người thân trong gia đình qua hình ảnh. | G16: Nhận biết mối quan hệ xã hội: Nhận biết vai trò của một số người xung quanh (cô giáo, bạn bè). | H16: Nhận biết mối quan hệ xã hội: Nhận biết và ứng xử phù hợp vị trí trong gia đình/trường/lớp/cộng đồng. | I16: Trẻ biết chào đúng cách với cô, ông bà, bạn bè theo từng vai trò.
... A39: 35 | B39: Vận dụng/Thành thạo | C39: Bé lớn lên mỗi ngày - Mùa hè vui | D39: Mùa hè vui của bé | E39: — | F39: — | G39: — | H39: — | I39: —

Sheet NGANHANGHD
A1: NGÂN HÀNG HOẠT ĐỘNG — MẪU GIÁO 3-6 TUỔI (30 HOẠT ĐỘNG MẪU) | R1: =HYPERLINK("#TRANGCHU!A1","⬅ Về Trang chủ") -> ⬅ Về Trang chủ | S1: =HYPERLINK("#HUONGDAN!A1","📖 Về Hướng dẫn") -> 📖 Về Hướng dẫn
A2: 10 chủ đề chung × 3 độ tuổi để thấy rõ tiến trình I→R→M. Mỗi hoạt động tích hợp LINH HOẠT ít nhất 2-3 lĩnh vực (xem cột Lĩnh vực tích hợp thêm) — KHÔNG tổ chức cứng theo 5 môn riêng biệt. Trẻ được lựa chọn cách làm, KHÔNG yêu cầu sản phẩm giống nhau hay giống mẫu của cô. Dùng Filter trên dòng tiêu đề để lọc theo Độ tuổi/Lĩnh vực.
A4: Mã HĐ | B4: Độ tuổi | C4: Chủ đề/Chủ đề nhánh | D4: Lĩnh vực chính | E4: Lĩnh vực tích hợp thêm | F4: Năng lực lĩnh vực | G4: Phẩm chất liên quan | H4: Năng lực nền tảng | I4: Mục tiêu quan sát được | J4: Chuẩn bị môi trường, học liệu | K4: Tiến trình tổ chức | L4: Câu hỏi gợi mở của GV | M4: Biểu hiện mong đợi | N4: Minh chứng đánh giá | O4: Điều chỉnh hòa nhập / hỗ trợ đặc biệt | P4: Mở rộng cho trẻ khá hơn
A5: MGB-HĐ01 | B5: 3-4 tuổi (MGB) | C5: Trường mầm non - Lớp học của bé / Bé và bạn mới | D5: Tình cảm - xã hội | E5: Ngôn ngữ, Nghệ thuật | F5: TX4 - Thiết lập và duy trì mối quan hệ xã hội | G5: Yêu thương | H5: Giao tiếp, Hợp tác | I5: Chơi cạnh bạn, bắt đầu làm quen khi có cô hỗ trợ giới thiệu. | J5: Đồ dùng cỡ lớn, dễ cầm nắm; không gian rộng, an toàn; hình ảnh/đồ vật thật quen thuộc. | K5: 1) Cô giới thiệu, làm mẫu trực tiếp. 2) Trẻ làm cùng cô, được hỗ trợ cầm tay/hướng dẫn từng bước. 3) Lặp lại 2-3 lần trong tuần để hình thành thói quen. 4) Cô khen ngợi, động viên khi trẻ cố gắng. | L5: Con thấy gì? Đây là cái gì? Con có muốn thử không? | M5: Trẻ tham gia khi được cô rủ/làm cùng; chơi cạnh bạn, bắt đầu làm quen khi có c... | N5: Trẻ tự làm hòa với bạn sau khi giận nhau, rủ bạn mới cùng chơi. | O5: Cô làm cùng 1-1, chia nhỏ thao tác, tăng thời gian chờ, dùng đồ vật quen thuộc hơn. | P5: Khuyến khích trẻ tự làm 1 bước nhỏ không cần cô cầm tay, khen khi trẻ tự thử.
A6: MGB-HĐ02 | B6: 3-4 tuổi (MGB) | C6: Bé là ai - Cơ thể và giác quan / Khám phá cơ thể bé | D6: Thể chất | E6: Nhận thức, Ngôn ngữ | F6: TC3 - Vận động thô | G6: — | H6: Tự lực | I6: Đi/chạy đường ngắn có cô cầm tay; giữ thăng bằng 1-2 giây có đỡ. | J6: Đồ dùng cỡ lớn, dễ cầm nắm; không gian rộng, an toàn; hình ảnh/đồ vật thật quen thuộc. | K6: 1) Cô giới thiệu, làm mẫu trực tiếp. 2) Trẻ làm cùng cô, được hỗ trợ cầm tay/hướng dẫn từng bước. 3) Lặp lại 2-3 lần trong tuần để hình thành thói quen. 4) Cô khen ngợi, động viên khi trẻ cố gắng. | L6: Con thấy gì? Đây là cái gì? Con có muốn thử không? | M6: Trẻ tham gia khi được cô rủ/làm cùng; đi/chạy đường ngắn có cô cầm tay; giữ th... | N6: Trẻ đi thăng bằng trên ghế thể dục cao 30cm không cần cô đỡ. | O6: Cô làm cùng 1-1, chia nhỏ thao tác, tăng thời gian chờ, dùng đồ vật quen thuộc hơn. | P6: Khuyến khích trẻ tự làm 1 bước nhỏ không cần cô cầm tay, khen khi trẻ tự thử.
A7: MGB-HĐ03 | B7: 3-4 tuổi (MGB) | C7: Gia đình yêu thương / Người thân trong gia đình | D7: Tình cảm - xã hội | E7: Ngôn ngữ, Nghệ thuật | F7: TX3 - Nhận biết mối quan hệ xã hội | G7: Tôn trọng | H7: Giao tiếp, Hợp tác | I7: Nhận biết người thân trong gia đình qua hình ảnh. | J7: Đồ dùng cỡ lớn, dễ cầm nắm; không gian rộng, an toàn; hình ảnh/đồ vật thật quen thuộc. | K7: 1) Cô giới thiệu, làm mẫu trực tiếp. 2) Trẻ làm cùng cô, được hỗ trợ cầm tay/hướng dẫn từng bước. 3) Lặp lại 2-3 lần trong tuần để hình thành thói quen. 4) Cô khen ngợi, động viên khi trẻ cố gắng. | L7: Con thấy gì? Đây là cái gì? Con có muốn thử không? | M7: Trẻ tham gia khi được cô rủ/làm cùng; nhận biết người thân trong gia đình qua ... | N7: Trẻ biết chào đúng cách với cô, ông bà, bạn bè theo từng vai trò. | O7: Cô làm cùng 1-1, chia nhỏ thao tác, tăng thời gian chờ, dùng đồ vật quen thuộc hơn. | P7: Khuyến khích trẻ tự làm 1 bước nhỏ không cần cô cầm tay, khen khi trẻ tự thử.
A8: MGB-HĐ04 | B8: 3-4 tuổi (MGB) | C8: Gia đình yêu thương (dinh dưỡng) / Bữa ăn của bé | D8: Thể chất | E8: Nhận thức, Tình cảm - xã hội | F8: TC5 - Thực hành ăn uống hợp lý | G8: Trách nhiệm | H8: Tự lực | I8: Gọi tên 1-2 món quen thuộc; bắt đầu tự xúc ăn, cần hỗ trợ một phần. | J8: Đồ dùng cỡ lớn, dễ cầm nắm; không gian rộng, an toàn; hình ảnh/đồ vật thật quen thuộc. | K8: 1) Cô giới thiệu, làm mẫu trực tiếp. 2) Trẻ làm cùng cô, được hỗ trợ cầm tay/hướng dẫn từng bước. 3) Lặp lại 2-3 lần trong tuần để hình thành thói quen. 4) Cô khen ngợi, động viên khi trẻ cố gắng. | L8: Con thấy gì? Đây là cái gì? Con có muốn thử không? | M8: Trẻ tham gia khi được cô rủ/làm cùng; gọi tên 1-2 món quen thuộc; bắt đầu tự x... | N8: Trẻ tự chọn và ăn đủ các nhóm thực phẩm trong bữa ăn tại lớp. | O8: Cô làm cùng 1-1, chia nhỏ thao tác, tăng thời gian chờ, dùng đồ vật quen thuộc hơn. | P8: Khuyến khích trẻ tự làm 1 bước nhỏ không cần cô cầm tay, khen khi trẻ tự thử.
A9: MGB-HĐ05 | B9: 3-4 tuổi (MGB) | C9: Nghề nghiệp quen thuộc / Nghề của người thân | D9: Ngôn ngữ | E9: Tình cảm - xã hội, Nghệ thuật | F9: NN2 - Diễn đạt bằng lời nói | G9: — | H9: Giao tiếp | I9: Nói câu ngắn 2-3 từ để nêu nhu cầu. | J9: Đồ dùng cỡ lớn, dễ cầm nắm; không gian rộng, an toàn; hình ảnh/đồ vật thật quen thuộc. | K9: 1) Cô giới thiệu, làm mẫu trực tiếp. 2) Trẻ làm cùng cô, được hỗ trợ cầm tay/hướng dẫn từng bước. 3) Lặp lại 2-3 lần trong tuần để hình thành thói quen. 4) Cô khen ngợi, động viên khi trẻ cố gắng. | L9: Con thấy gì? Đây là cái gì? Con có muốn thử không? | M9: Trẻ tham gia khi được cô rủ/làm cùng; nói câu ngắn 2-3 từ để nêu nhu cầu.... | N9: Trẻ trình bày ý kiến rõ ràng trước nhóm bạn khi thảo luận. | O9: Cô làm cùng 1-1, chia nhỏ thao tác, tăng thời gian chờ, dùng đồ vật quen thuộc hơn. | P9: Khuyến khích trẻ tự làm 1 bước nhỏ không cần cô cầm tay, khen khi trẻ tự thử.
A10: MGB-HĐ06 | B10: 3-4 tuổi (MGB) | C10: Thế giới động vật / Vật nuôi trong nhà | D10: Nhận thức | E10: Ngôn ngữ, Nghệ thuật | F10: NT3 - Hiểu biết ban đầu về thế giới xung quanh | G10: — | H10: Giải quyết vấn đề | I10: Gọi tên 1-2 đặc điểm nổi bật của sự vật quen thuộc. | J10: Đồ dùng cỡ lớn, dễ cầm nắm; không gian rộng, an toàn; hình ảnh/đồ vật thật quen thuộc. | K10: 1) Cô giới thiệu, làm mẫu trực tiếp. 2) Trẻ làm cùng cô, được hỗ trợ cầm tay/hướng dẫn từng bước. 3) Lặp lại 2-3 lần trong tuần để hình thành thói quen. 4) Cô khen ngợi, động viên khi trẻ cố gắng. | L10: Con thấy gì? Đây là cái gì? Con có muốn thử không? | M10: Trẻ tham gia khi được cô rủ/làm cùng; gọi tên 1-2 đặc điểm nổi bật của sự vật ... | N10: Trẻ mô tả được quá trình cây lớn lên qua các giai đoạn quan sát. | O10: Cô làm cùng 1-1, chia nhỏ thao tác, tăng thời gian chờ, dùng đồ vật quen thuộc hơn. | P10: Khuyến khích trẻ tự làm 1 bước nhỏ không cần cô cầm tay, khen khi trẻ tự thử.
A11: MGB-HĐ07 | B11: 3-4 tuổi (MGB) | C11: Thế giới thực vật / Cây lớn lên thế nào | D11: Nhận thức | E11: Thể chất, Nhận thức | F11: NT5 - Giải quyết vấn đề đơn giản | G11: — | H11: Giải quyết vấn đề | I11: Nhận biết có vấn đề cần giải quyết khi cô gợi ý (đồ chơi rơi...). | J11: Đồ dùng cỡ lớn, dễ cầm nắm; không gian rộng, an toàn; hình ảnh/đồ vật thật quen thuộc. | K11: 1) Cô giới thiệu, làm mẫu trực tiếp. 2) Trẻ làm cùng cô, được hỗ trợ cầm tay/hướng dẫn từng bước. 3) Lặp lại 2-3 lần trong tuần để hình thành thói quen. 4) Cô khen ngợi, động viên khi trẻ cố gắng. | L11: Con thấy gì? Đây là cái gì? Con có muốn thử không? | M11: Trẻ tham gia khi được cô rủ/làm cùng; nhận biết có vấn đề cần giải quyết khi c... | N11: Trẻ tự đề xuất và thử nghiệm cách sửa mô hình bị đổ. | O11: Cô làm cùng 1-1, chia nhỏ thao tác, tăng thời gian chờ, dùng đồ vật quen thuộc hơn. | P11: Khuyến khích trẻ tự làm 1 bước nhỏ không cần cô cầm tay, khen khi trẻ tự thử.
A12: MGB-HĐ08 | B12: 3-4 tuổi (MGB) | C12: Giao thông / Phương tiện giao thông quanh bé | D12: Tình cảm - xã hội | E12: Nhận thức, Ngôn ngữ | F12: TX7 - Ứng xử phù hợp với hoàn cảnh | G12: Tôn trọng | H12: Thích ứng | I12: Làm theo hướng dẫn đơn giản của cô trong sinh hoạt quen thuộc. | J12: Đồ dùng cỡ lớn, dễ cầm nắm; không gian rộng, an toàn; hình ảnh/đồ vật thật quen thuộc. | K12: 1) Cô giới thiệu, làm mẫu trực tiếp. 2) Trẻ làm cùng cô, được hỗ trợ cầm tay/hướng dẫn từng bước. 3) Lặp lại 2-3 lần trong tuần để hình thành thói quen. 4) Cô khen ngợi, động viên khi trẻ cố gắng. | L12: Con thấy gì? Đây là cái gì? Con có muốn thử không? | M12: Trẻ tham gia khi được cô rủ/làm cùng; làm theo hướng dẫn đơn giản của cô trong... | N12: Trẻ tự biết giữ trật tự khi đi tham quan, lễ phép khi có khách đến lớp. | O12: Cô làm cùng 1-1, chia nhỏ thao tác, tăng thời gian chờ, dùng đồ vật quen thuộc hơn. | P12: Khuyến khích trẻ tự làm 1 bước nhỏ không cần cô cầm tay, khen khi trẻ tự thử.
A13: MGB-HĐ09 | B13: 3-4 tuổi (MGB) | C13: Nước và hiện tượng tự nhiên / Bí mật của nước | D13: Nhận thức | E13: Thể chất, Nghệ thuật | F13: NT2 - Chủ động khám phá và giải quyết vấn đề | G13: — | H13: Giải quyết vấn đề | I13: Khám phá đồ vật đơn giản khi có cô cùng làm. | J13: Đồ dùng cỡ lớn, dễ cầm nắm; không gian rộng, an toàn; hình ảnh/đồ vật thật quen thuộc. | K13: 1) Cô giới thiệu, làm mẫu trực tiếp. 2) Trẻ làm cùng cô, được hỗ trợ cầm tay/hướng dẫn từng bước. 3) Lặp lại 2-3 lần trong tuần để hình thành thói quen. 4) Cô khen ngợi, động viên khi trẻ cố gắng. | L13: Con thấy gì? Đây là cái gì? Con có muốn thử không? | M13: Trẻ tham gia khi được cô rủ/làm cùng; khám phá đồ vật đơn giản khi có cô cùng ... | N13: Trẻ tự thử nhiều cách khác nhau để hoàn thành thử thách xây dựng STEAM. | O13: Cô làm cùng 1-1, chia nhỏ thao tác, tăng thời gian chờ, dùng đồ vật quen thuộc hơn. | P13: Khuyến khích trẻ tự làm 1 bước nhỏ không cần cô cầm tay, khen khi trẻ tự thử.
A14: MGB-HĐ10 | B14: 3-4 tuổi (MGB) | C14: Quê hương - Đất nước - Bác Hồ / Quê hương của bé | D14: Nghệ thuật | E14: Ngôn ngữ, Tình cảm - xã hội | F14: NgT1 - Cảm thụ vẻ đẹp trong cuộc sống và nghệ thuật | G14: Yêu thương | H14: — | I14: Chú ý, tỏ thích thú trước cái đẹp khi cô chỉ ra. | J14: Đồ dùng cỡ lớn, dễ cầm nắm; không gian rộng, an toàn; hình ảnh/đồ vật thật quen thuộc. | K14: 1) Cô giới thiệu, làm mẫu trực tiếp. 2) Trẻ làm cùng cô, được hỗ trợ cầm tay/hướng dẫn từng bước. 3) Lặp lại 2-3 lần trong tuần để hình thành thói quen. 4) Cô khen ngợi, động viên khi trẻ cố gắng. | L14: Con thấy gì? Đây là cái gì? Con có muốn thử không? | M14: Trẻ tham gia khi được cô rủ/làm cùng; chú ý, tỏ thích thú trước cái đẹp khi cô... | N14: Trẻ tự chỉ và nói vì sao mình thích một bức tranh/bản nhạc. | O14: Cô làm cùng 1-1, chia nhỏ thao tác, tăng thời gian chờ, dùng đồ vật quen thuộc hơn. | P14: Khuyến khích trẻ tự làm 1 bước nhỏ không cần cô cầm tay, khen khi trẻ tự thử.
A15: MGN-HĐ01 | B15: 4-5 tuổi (MGN) | C15: Trường mầm non - Lớp học của bé / Bé và bạn mới | D15: Tình cảm - xã hội | E15: Ngôn ngữ, Nghệ thuật | F15: TX4 - Thiết lập và duy trì mối quan hệ xã hội | G15: Yêu thương | H15: Giao tiếp, Hợp tác | I15: Chủ động rủ bạn chơi cùng; duy trì chơi nhóm nhỏ trong thời gian ngắn. | J15: Đồ dùng đa dạng hơn, đủ cho nhóm nhỏ 2-4 trẻ dùng chung; góc hoạt động có khay vật liệu. | K15: 1) Cô gợi mở bằng câu hỏi, giới thiệu nhiệm vụ nhóm nhỏ. 2) Trẻ tự thực hiện theo nhóm 2-4 bạn, cô quan sát và gợi ý khi cần. 3) Nhóm chia sẻ lại điều đã làm/thấy. 4) Cô tổng kết, khen các biểu hiện hợp tác. | L15: Nhóm con định làm gì? Vì sao con nghĩ vậy? Con và bạn chia việc thế nào? | M15: Trẻ chủ động tham gia nhóm nhỏ; chủ động rủ bạn chơi cùng; duy trì chơi nhóm nhỏ t... | N15: Trẻ tự làm hòa với bạn sau khi giận nhau, rủ bạn mới cùng chơi. | O15: Ghép cùng bạn tự tin hơn, cô gợi ý câu hỏi đơn giản hơn, rút ngắn nhiệm vụ. | P15: Giao thêm vai trò trưởng nhóm nhỏ, khuyến khích tự đặt thêm câu hỏi khám phá.
... A34: MGL-HĐ10 | B34: 5-6 tuổi (MGL) | C34: Quê hương - Đất nước - Bác Hồ / Quê hương của bé | D34: Nghệ thuật | E34: Ngôn ngữ, Tình cảm - xã hội | F34: NgT1 - Cảm thụ vẻ đẹp trong cuộc sống và nghệ thuật | G34: Yêu thương | H34: — | I34: Yêu thích, trân trọng sản phẩm nghệ thuật, cái đẹp trong cuộc sống và truyền thống. | J34: Học liệu mở, nhiều lựa chọn; góc trải nghiệm/dự án; dụng cụ ghi chép đơn giản (giấy, bút). | K34: 1) HỎI: trẻ tự nêu vấn đề/câu hỏi muốn khám phá. 2) TƯỞNG TƯỢNG - LẬP KẾ HOẠCH: nhóm bàn cách thực hiện, phân công vai trò. 3) SÁNG TẠO: tự thực hiện, cô chỉ hỗ trợ khi được yêu cầu. 4) CHIA SẺ - CẢI TIẾN: trình bày sản phẩm, nhận góp ý và điều chỉnh. | L34: Vì sao con chọn cách này? Nếu làm lại con sẽ thay đổi gì? Điều gì con tự hào nhất? | M34: Trẻ chủ động, tự tin trình bày và bảo vệ ý tưởng; yêu thích, trân trọng sản phẩm nghệ thuật, cái đẹp... | N34: Trẻ tự chỉ và nói vì sao mình thích một bức tranh/bản nhạc. | O34: Chia nhỏ vấn đề thành các bước rõ ràng hơn, ghép nhóm hỗ trợ, cô đặt câu hỏi dẫn dắt nhiều hơn. | P34: Khuyến khích mở rộng dự án, kết nối với chủ đề khác, tự thiết kế thêm biến thể sáng tạo.

Sheet NGANHANGHL
A1: NGÂN HÀNG HỌC LIỆU — MẪU GIÁO 3-6 TUỔI | G1: =HYPERLINK("#TRANGCHU!A1","⬅ Về Trang chủ") -> ⬅ Về Trang chủ | H1: =HYPERLINK("#HUONGDAN!A1","📖 Về Hướng dẫn") -> 📖 Về Hướng dẫn
A2: Danh mục học liệu/đồ dùng theo 10 chủ đề chung, ưu tiên học liệu mở, tái chế, gắn địa phương. Dùng Filter để lọc theo Nguồn gốc khi cần chuẩn bị/mua sắm.
A4: Chủ đề lớn | B4: Học liệu / Đồ dùng | C4: Nguồn gốc | D4: Độ tuổi phù hợp | E4: Ghi chú sử dụng
A5: Trường mầm non - Lớp học của bé | B5: Khối gỗ/nhựa cỡ lớn, đồ chơi góc phân vai (bát, thìa nhựa) | C5: Mua sẵn | D5: Cả 3 độ tuổi | E5: Chọn kích thước lớn cho MGB, chi tiết hơn cho MGN/MGL
A6: Bé là ai - Cơ thể và giác quan | B6: Gương soi an toàn, tranh sơ đồ cơ thể, hộp cảm giác (mùi/vị) | C6: Mua sẵn + tự làm | D6: Cả 3 độ tuổi | E6: Hộp cảm giác tự làm từ hộp giấy, vải vụn
A7: Gia đình yêu thương | B7: Ảnh gia đình trẻ mang từ nhà, đồ chơi nấu ăn, mô hình nhà | C7: Từ gia đình + mua sẵn | D7: Cả 3 độ tuổi | E7: Khuyến khích phụ huynh gửi ảnh thật
A8: Nghề nghiệp quen thuộc | B8: Trang phục hóa trang nghề (mũ bác sĩ, mũ bảo hộ), dụng cụ mô phỏng | C8: Mua sẵn + tái chế | D8: Cả 3 độ tuổi | E8: Có thể mượn từ phụ huynh làm nghề liên quan
A9: Thế giới động vật gần gũi | B9: Mô hình con vật, tranh ảnh, thức ăn giả cho vật nuôi lớp | C9: Mua sẵn | D9: Cả 3 độ tuổi | E9: Ưu tiên vật nuôi thật ở góc thiên nhiên nếu điều kiện cho phép
A10: Thế giới thực vật - Tết | B10: Hạt giống, chậu nhỏ, dụng cụ làm đồ trang trí Tết địa phương | C10: Tự nhiên + địa phương | D10: Cả 3 độ tuổi | E10: Gắn đặc sản/phong tục địa phương (VD: hoa đào Tuyên Quang)
A11: Bé và phương tiện giao thông | B11: Mô hình xe, biển báo tự làm, thùng carton làm ô tô/thuyền | C11: Mua sẵn + tái chế | D11: Cả 3 độ tuổi | E11: Thùng carton tái chế phù hợp hoạt động STEAM
A12: Nước và hiện tượng tự nhiên | B12: Chậu nước, vật nổi/chìm (nút chai, đá, bóng), cốc đo | C12: Tự nhiên + tái chế | D12: Cả 3 độ tuổi | E12: An toàn: luôn có GV giám sát khi chơi với nước
A13: Quê hương - Đất nước - Bác Hồ | B13: Tranh ảnh danh lam địa phương, cờ Tổ quốc, ảnh Bác Hồ | C13: Mua sẵn + địa phương | D13: Cả 3 độ tuổi | E13: Liên hệ di tích/danh lam có thật tại địa phương trường đóng
A14: Bé lớn lên - Mùa hè vui | B14: Album ảnh cả năm, sản phẩm lưu giữ, dụng cụ vận động ngoài trời hè | C14: Tự làm từ Portfolio | D14: Cả 3 độ tuổi | E14: Dùng chính dữ liệu từ sheet PORTFOLIO để làm album tổng kết

Sheet RUBRIC
A1: RUBRIC ĐÁNH GIÁ NĂNG LỰC — MẪU GIÁO 3-6 TUỔI | J1: =HYPERLINK("#TRANGCHU!A1","⬅ Về Trang chủ") -> ⬅ Về Trang chủ | K1: =HYPERLINK("#HUONGDAN!A1","📖 Về Hướng dẫn") -> 📖 Về Hướng dẫn
A2: Thang 3 mức: I - Khởi đầu · H - Hình thành · V - Vững chắc · X = Chưa có cơ hội quan sát (không suy diễn).
